{
 "cells": [
  {
   "cell_type": "markdown",
   "metadata": {},
   "source": [
    "# kata Módulo 10"
   ]
  },
  {
   "cell_type": "markdown",
   "metadata": {},
   "source": [
    "## ¿Qué descubríras?\n",
    "Al término de este módulo, sabrás hacer lo siguiente:\n",
    "\n",
    "    - Leer y usar la salida de errores de las excepciones Controlar correctamente las excepciones\n",
    "    - Generar excepciones con mensajes de error útiles\n",
    "    - Usar excepciones para controlar el flujo de un programa"
   ]
  },
  {
   "cell_type": "markdown",
   "metadata": {},
   "source": [
    "#### Uso de Tracebacks para buscar errores\n",
    "Las excepciones en Python son una característica principal del lenguaje. Es posible que te sorprenda leer que algo que genera errores se resalta como una característica. Esta sorpresa puede deberse a que las herramientas de software sólidas no parecen bloquearse con un traceback seguimiento (varias líneas de texto que indican cómo se inició y finalizó el error).\n",
    "\n",
    "Sin embargo, las excepciones son útiles porque ayudan en la toma de decisiones generando mensajes de error descriptivos. Pueden ayudarte a controlar los problemas esperados e inesperados."
   ]
  },
  {
   "cell_type": "markdown",
   "metadata": {},
   "source": [
    "#### Tracebacks\n",
    "Un traceback es el cuerpo del texto que puede apuntar al origen (y al final) de un error no controlado. Comprender los componentes de un traceback hará que seas más eficaz al corregir errores o depurar un programa que no funciona bien.\n",
    "\n",
    "La primera vez que encuentres excepciones en Python podrías verte tentado/a a evitar el error suprimiéndolo. Cuando un programa sufre un error no controlado, aparece un traceback como salida. Como verás en este módulo, los tracebacks son útiles. Hay maneras de controlar correctamente los errores para que no aparezcan o muestren información útil.\n",
    "\n",
    "Si intentamos en un notebook, abrir un archivo inexistente sucede lo siguiente:"
   ]
  },
  {
   "cell_type": "code",
   "execution_count": 1,
   "metadata": {},
   "outputs": [
    {
     "ename": "FileNotFoundError",
     "evalue": "[Errno 2] No such file or directory: '/path/to/mars.jpg'",
     "output_type": "error",
     "traceback": [
      "\u001b[1;31m---------------------------------------------------------------------------\u001b[0m",
      "\u001b[1;31mFileNotFoundError\u001b[0m                         Traceback (most recent call last)",
      "\u001b[1;32md:\\Users\\EmmaD\\Documents\\10 - PRACTICE\\WEB DEV\\3 - COURSES\\LAUNCH_X\\LAUNCH_X-SEMANA_1\\10 - Manejo de Errores\\Kata & Módulo 10\\kata-modulo_10.ipynb Cell 2'\u001b[0m in \u001b[0;36m<module>\u001b[1;34m\u001b[0m\n\u001b[1;32m----> <a href='vscode-notebook-cell:/d%3A/Users/EmmaD/Documents/10%20-%20PRACTICE/WEB%20DEV/3%20-%20COURSES/LAUNCH_X/LAUNCH_X-SEMANA_1/10%20-%20Manejo%20de%20Errores/Kata%20%26%20M%C3%B3dulo%2010/kata-modulo_10.ipynb#ch0000000?line=0'>1</a>\u001b[0m \u001b[39mopen\u001b[39;49m(\u001b[39m\"\u001b[39;49m\u001b[39m/path/to/mars.jpg\u001b[39;49m\u001b[39m\"\u001b[39;49m)\n",
      "\u001b[1;31mFileNotFoundError\u001b[0m: [Errno 2] No such file or directory: '/path/to/mars.jpg'"
     ]
    }
   ],
   "source": [
    "open(\"/path/to/mars.jpg\")"
   ]
  },
  {
   "cell_type": "markdown",
   "metadata": {},
   "source": [
    "Esa salida tiene varias partes clave. En primer lugar, el traceback menciona el orden de la salida. Después, informa de que el archivo es stdin (entrada en el terminal interactivo) en la primera línea de la entrada. El error es FileNotFoundError (el nombre de excepción), lo que significa que el archivo no existe o quizás el directorio correspondiente no existe.\n",
    "\n",
    "Es mucha información. Puede ser difícil entender por qué la línea 1 es significativa o qué significa Errno 2.\n",
    "\n",
    "Intenta crear un archivo de Python y asígnale el nombre open.py, con el contenido siguiente:"
   ]
  },
  {
   "cell_type": "code",
   "execution_count": null,
   "metadata": {},
   "outputs": [],
   "source": [
    "def main():\n",
    "    open(\"/path/to/mars.jpg\")\n",
    "\n",
    "if __name__ == '__main__':\n",
    "    main()"
   ]
  },
  {
   "cell_type": "markdown",
   "metadata": {},
   "source": [
    "Se trata de una sola función main() que abre el archivo inexistente, como antes. Al final, esta función usa un asistente de Python que indica al intérprete que ejecute la función main() cuando se le llama en el terminal. Ejecútala con Python y podrás comprobar el siguiente mensaje de error:"
   ]
  },
  {
   "cell_type": "code",
   "execution_count": null,
   "metadata": {},
   "outputs": [],
   "source": [
    "$ python3 open.py\n",
    "Traceback (most recent call last):\n",
    "  File \"/tmp/open.py\", line 5, in <module>\n",
    "    main()\n",
    "  File \"/tmp/open.py\", line 2, in main\n",
    "    open(\"/path/to/mars.jpg\")\n",
    "FileNotFoundError: [Errno 2] No such file or directory: '/path/to/mars.jpg'"
   ]
  },
  {
   "cell_type": "markdown",
   "metadata": {},
   "source": [
    "La salida de error tiene más sentido ahora. Las rutas de acceso apuntan a un único archivo denominado open.py. La salida menciona que el error se inicia en la línea 5, que incluye la llamada a main(). A continuación, la salida sigue el error a la línea 2 en la llamada de función open(). Y, por último, FileNotFoundError notifica de nuevo que el archivo o el directorio no existen.\n",
    "\n",
    "Los tracebacks casi siempre incluyen la información siguiente:\n",
    "\n",
    "    - Todas las rutas de acceso de archivo implicadas, para cada llamada a cada función.\n",
    "    - Los números de línea asociados a cada ruta de acceso de archivo.\n",
    "    - Los nombres de las funciones, métodos o clases implicados en la generación de una excepción.\n",
    "    - El nombre de la excepción que se ha producido."
   ]
  },
  {
   "cell_type": "markdown",
   "metadata": {},
   "source": [
    "#### Controlando las excepciones\n",
    "Cuando encuentres por primera vez excepciones que muestren tracebacks grandes como salida, es posible que te veas tentado/a a detectar todos los errores para evitar que esto suceda.\n",
    "\n",
    "Si estás en una misión a Marte, ¿Qué podrías hacer si un texto del sistema de navegación dice 'Se ha producido un error'? Imagina que no hay ninguna más información ni contexto, simplemente una luz roja parpadeante con el texto del error. Como desarrollador, resulta útil ponerse al otro lado del programa: ¿Qué puede hacer un usuario cuando se produce un error?\n",
    "\n",
    "Aunque en este módulo se explica cómo controlar las excepciones detectándolas, no es necesario detectar las excepciones todo el tiempo. A veces resulta útil permitir que se puedan generar excepciones para que otros autores de llamadas puedan tratar los errores.\n",
    "\n"
   ]
  },
  {
   "cell_type": "markdown",
   "metadata": {},
   "source": [
    "#### Try y Except de los bloques\n",
    "Vamos a usar el ejemplo de navegador a fin de crear código que abra archivos de configuración para la misión de Marte. Los archivos de configuración pueden tener todo tipo de problemas, por lo que es fundamental notificarlos con precisión cuando se presenten. Sabemos que, si no existe un archivo o directorio, se genera FileNotFoundError. Si queremos controlar esa excepción, podemos hacerlo con un bloque try y except:\n",
    "\n"
   ]
  },
  {
   "cell_type": "code",
   "execution_count": 2,
   "metadata": {},
   "outputs": [
    {
     "name": "stdout",
     "output_type": "stream",
     "text": [
      "Couldn't find the config.txt file!\n"
     ]
    }
   ],
   "source": [
    "try:\n",
    "    open('config.txt')\n",
    "except FileNotFoundError:\n",
    "    print(\"Couldn't find the config.txt file!\")\n"
   ]
  },
  {
   "cell_type": "markdown",
   "metadata": {},
   "source": [
    "Después de la palabra clave try, agregamos código que tenga la posibilidad de producir una excepción. A continuación, agregamos la palabra clave except junto con la posible excepción, seguida de cualquier código que deba ejecutarse cuando se produce esa condición. Puesto que config.txt no existe en el sistema, Python imprime que el archivo de configuración no está ahí. El bloque try y except, junto con un mensaje útil, evita un seguimiento y sigue informando al usuario sobre el problema.\n",
    "\n",
    "Aunque es común un archivo que no existe, no es el único error que podemos encontrar. Los permisos de archivo no válidos pueden impedir la lectura de un archivo, incluso si este existe. Vamos a crear un archivo de Python denominado config.py. El archivo tiene código que busca y lee el archivo de configuración del sistema de navegación:"
   ]
  },
  {
   "cell_type": "code",
   "execution_count": 5,
   "metadata": {},
   "outputs": [],
   "source": [
    "def main():\n",
    "    try:\n",
    "        configuration = open('config.txt')\n",
    "    except FileNotFoundError:\n",
    "        print(\"Couldn't find the config.txt file!\")\n",
    "\n",
    "\n",
    "if __name__ == '__main__':\n",
    "    main()"
   ]
  },
  {
   "cell_type": "markdown",
   "metadata": {},
   "source": [
    "A continuación, quita,ps el archivo config.txt y creamos un directorio denominado config.txt. Intentaremos llamar al archivo config.py para ver un error nuevo que debería ser similar al siguiente:\n",
    "\n",
    "    "
   ]
  },
  {
   "cell_type": "code",
   "execution_count": 4,
   "metadata": {},
   "outputs": [],
   "source": [
    "$ python config.py\n",
    "Traceback (most recent call last):\n",
    "  File \"/tmp/config.py\", line 9, in <module>\n",
    "    main()\n",
    "  File \"/tmp/config.py\", line 3, in main\n",
    "    configuration = open('config.txt')\n",
    "IsADirectoryError: [Errno 21] Is a directory: 'config.txt'"
   ]
  },
  {
   "cell_type": "markdown",
   "metadata": {},
   "source": [
    "Una manera poco útil de controlar este error sería detectar todas las excepciones posibles para evitar un traceback. Para comprender por qué detectar todas las excepciones es problemático, probaremos actualizando la función main():"
   ]
  },
  {
   "cell_type": "code",
   "execution_count": null,
   "metadata": {},
   "outputs": [],
   "source": [
    "def main():\n",
    "    try:\n",
    "        configuration = open('config.txt')\n",
    "    except Exception:\n",
    "        print(\"Couldn't find the config.txt file!\")"
   ]
  },
  {
   "cell_type": "markdown",
   "metadata": {},
   "source": [
    "Ahora volvemos a ejecutar el código en el mismo lugar donde existe el archivo config.txt con permisos incorrectos:\n",
    "\n"
   ]
  },
  {
   "cell_type": "code",
   "execution_count": null,
   "metadata": {},
   "outputs": [],
   "source": [
    "$ python config.py\n",
    "Couldn't find the config.txt file!"
   ]
  },
  {
   "cell_type": "markdown",
   "metadata": {},
   "source": [
    "El problema ahora es que el mensaje de error es incorrecto. El archivo existe, pero tiene permisos diferentes y Python no puede leerlo. Cuando se trata con errores de software, puede resultar frustrante tener errores que hagan lo siguiente:\n",
    "\n",
    "    - No indiquen cuál es el problema real.\n",
    "    - Proporcionen una salida que no coincida con el problema real.\n",
    "    - No sugieran lo que se puede hacer para corregir el problema."
   ]
  },
  {
   "cell_type": "markdown",
   "metadata": {},
   "source": [
    "Vamos a corregir este fragmento de código para abordar todas estas frustraciones. Revertiremos la detección de FileNotFoundError y luego agregamos otro bloque except para detectar PermissionError:"
   ]
  },
  {
   "cell_type": "code",
   "execution_count": null,
   "metadata": {},
   "outputs": [],
   "source": [
    "def main():\n",
    "    try:\n",
    "        configuration = open('config.txt')\n",
    "    except FileNotFoundError:\n",
    "        print(\"Couldn't find the config.txt file!\")\n",
    "    except IsADirectoryError:\n",
    "        print(\"Found config.txt but it is a directory, couldn't read it\")"
   ]
  },
  {
   "cell_type": "markdown",
   "metadata": {},
   "source": [
    "Ahora volvemos a ejecutarlo, en el mismo lugar donde config.txt está con el problema de permisos:\n",
    "\n"
   ]
  },
  {
   "cell_type": "code",
   "execution_count": null,
   "metadata": {},
   "outputs": [],
   "source": [
    "$ python config.py\n",
    "Found config.txt but couldn't read it"
   ]
  },
  {
   "cell_type": "markdown",
   "metadata": {},
   "source": [
    "Eliminamos el archivo config.txt para asegurarnos de que se alcanza el primer bloque except en su lugar:\n",
    "\n"
   ]
  },
  {
   "cell_type": "code",
   "execution_count": null,
   "metadata": {},
   "outputs": [],
   "source": [
    "$ rm -f config.txt\n",
    "$ python config.py\n",
    "Couldn't find the config.txt file!"
   ]
  },
  {
   "cell_type": "markdown",
   "metadata": {},
   "source": [
    "Cuando los errores son de una naturaleza similar y no es necesario controlarlos individualmente, puedes agrupar las excepciones como una usando paréntesis en la línea except. Por ejemplo, si el sistema de navegación está bajo cargas pesadas y el sistema de archivos está demasiado ocupado, tiene sentido detectar BlockingIOError y TimeOutError juntos:\n",
    "\n"
   ]
  },
  {
   "cell_type": "code",
   "execution_count": null,
   "metadata": {},
   "outputs": [],
   "source": [
    "def main():\n",
    "    try:\n",
    "        configuration = open('config.txt')\n",
    "    except FileNotFoundError:\n",
    "        print(\"Couldn't find the config.txt file!\")\n",
    "    except IsADirectoryError:\n",
    "        print(\"Found config.txt but it is a directory, couldn't read it\")\n",
    "    except (BlockingIOError, TimeoutError):\n",
    "        print(\"Filesystem under heavy load, can't complete reading configuration file\")"
   ]
  },
  {
   "cell_type": "markdown",
   "metadata": {},
   "source": [
    "#### Sugerencia\n",
    "Aunque puedes agrupar excepciones, solo debes hacerlo cuando no sea necesario controlarlas individualmente. Evita agrupar muchas excepciones para proporcionar un mensaje de error generalizado.\n",
    "\n",
    "Si necesitas acceder al error asociado a la excepción, debes actualizar la línea except para incluir la palabra clave as. Esta técnica es práctica si una excepción es demasiado genérica y el mensaje de error puede ser útil:"
   ]
  },
  {
   "cell_type": "code",
   "execution_count": null,
   "metadata": {},
   "outputs": [],
   "source": [
    ">>> try:\n",
    "...     open(\"mars.jpg\")\n",
    "... except FileNotFoundError as err:\n",
    "...     print(\"got a problem trying to read the file:\", err)\n",
    "...\n",
    "got a problem trying to read the file: [Errno 2] No such file or directory: 'mars.jpg'"
   ]
  },
  {
   "cell_type": "markdown",
   "metadata": {},
   "source": [
    "En este caso, as err significa que err se convierte en una variable con el objeto de excepción como valor. Después, usa este valor para imprimir el mensaje de error asociado a la excepción. Otra razón para usar esta técnica es acceder directamente a los atributos del error. Por ejemplo, si detecta una excepción OSError más genérica, que es la excepción primaria de FilenotFoundError y PermissionError, podemos diferenciarlas mediante el atributo .errno:\n",
    "\n"
   ]
  },
  {
   "cell_type": "code",
   "execution_count": null,
   "metadata": {},
   "outputs": [],
   "source": [
    ">>> try:\n",
    "...     open(\"config.txt\")\n",
    "... except OSError as err:\n",
    "...     if err.errno == 2:\n",
    "...         print(\"Couldn't find the config.txt file!\")\n",
    "...     elif err.errno == 13:\n",
    "...         print(\"Found config.txt but couldn't read it\")\n",
    "...\n",
    "Couldn't find the config.txt file!"
   ]
  },
  {
   "cell_type": "markdown",
   "metadata": {},
   "source": [
    "Intenta usar siempre la técnica que proporcione la mejor legibilidad para el código y que ayude a mantenerlo en el futuro. A veces es necesario usar código menos legible para ofrecer una mejor experiencia de usuario cuando se produce un error."
   ]
  },
  {
   "cell_type": "markdown",
   "metadata": {},
   "source": [
    "#### Generación de Excepciones\n",
    "Ahora que tienes una buena comprensión de los tracebacks y el control de excepciones, vamos a revisar la generación de excepciones.\n",
    "\n",
    "Es posible que ya conozcas una situación que podría provocar una condición de error al escribir código. En estas situaciones, resulta útil generar excepciones que permitan que otro código comprenda cuál es el problema.\n",
    "\n",
    "La generación de excepciones también puede ayudar en la toma de decisiones para otro código. Como hemos visto antes, en función del error, el código puede tomar decisiones inteligentes para resolver, solucionar o ignorar un problema.\n",
    "\n",
    "Los astronautas limitan su uso de agua a unos 11 litros al día. Vamos a crear una función que, con base al número de astronautas, pueda calcular la cantidad de agua quedará después de un día o más:"
   ]
  },
  {
   "cell_type": "code",
   "execution_count": 6,
   "metadata": {},
   "outputs": [],
   "source": [
    "def water_left(astronauts, water_left, days_left):\n",
    "    daily_usage = astronauts * 11\n",
    "    total_usage = daily_usage * days_left\n",
    "    total_water_left = water_left - total_usage\n",
    "\n",
    "    return f'Total Water left after {days_left} days is: {total_water_left} liters'"
   ]
  },
  {
   "cell_type": "markdown",
   "metadata": {},
   "source": [
    "PruProbemos con cinco astronautas, 100 litros de agua sobrante y dos días:"
   ]
  },
  {
   "cell_type": "code",
   "execution_count": 9,
   "metadata": {},
   "outputs": [
    {
     "ename": "RuntimeError",
     "evalue": "There is not enough water for 5 astronauts after 2 days!",
     "output_type": "error",
     "traceback": [
      "\u001b[1;31m---------------------------------------------------------------------------\u001b[0m",
      "\u001b[1;31mRuntimeError\u001b[0m                              Traceback (most recent call last)",
      "\u001b[1;32md:\\Users\\EmmaD\\Documents\\10 - PRACTICE\\WEB DEV\\3 - COURSES\\LAUNCH_X\\LAUNCH_X-SEMANA_1\\10 - Manejo de Errores\\Kata & Módulo 10\\kata-modulo_10.ipynb Cell 39'\u001b[0m in \u001b[0;36m<module>\u001b[1;34m\u001b[0m\n\u001b[1;32m----> <a href='vscode-notebook-cell:/d%3A/Users/EmmaD/Documents/10%20-%20PRACTICE/WEB%20DEV/3%20-%20COURSES/LAUNCH_X/LAUNCH_X-SEMANA_1/10%20-%20Manejo%20de%20Errores/Kata%20%26%20M%C3%B3dulo%2010/kata-modulo_10.ipynb#ch0000043?line=0'>1</a>\u001b[0m water_left(\u001b[39m5\u001b[39;49m, \u001b[39m100\u001b[39;49m, \u001b[39m2\u001b[39;49m)\n",
      "\u001b[1;32md:\\Users\\EmmaD\\Documents\\10 - PRACTICE\\WEB DEV\\3 - COURSES\\LAUNCH_X\\LAUNCH_X-SEMANA_1\\10 - Manejo de Errores\\Kata & Módulo 10\\kata-modulo_10.ipynb Cell 41'\u001b[0m in \u001b[0;36mwater_left\u001b[1;34m(astronauts, water_left, days_left)\u001b[0m\n\u001b[0;32m      <a href='vscode-notebook-cell:/d%3A/Users/EmmaD/Documents/10%20-%20PRACTICE/WEB%20DEV/3%20-%20COURSES/LAUNCH_X/LAUNCH_X-SEMANA_1/10%20-%20Manejo%20de%20Errores/Kata%20%26%20M%C3%B3dulo%2010/kata-modulo_10.ipynb#ch0000046?line=3'>4</a>\u001b[0m total_water_left \u001b[39m=\u001b[39m water_left \u001b[39m-\u001b[39m total_usage\n\u001b[0;32m      <a href='vscode-notebook-cell:/d%3A/Users/EmmaD/Documents/10%20-%20PRACTICE/WEB%20DEV/3%20-%20COURSES/LAUNCH_X/LAUNCH_X-SEMANA_1/10%20-%20Manejo%20de%20Errores/Kata%20%26%20M%C3%B3dulo%2010/kata-modulo_10.ipynb#ch0000046?line=4'>5</a>\u001b[0m \u001b[39mif\u001b[39;00m total_water_left \u001b[39m<\u001b[39m \u001b[39m0\u001b[39m:\n\u001b[1;32m----> <a href='vscode-notebook-cell:/d%3A/Users/EmmaD/Documents/10%20-%20PRACTICE/WEB%20DEV/3%20-%20COURSES/LAUNCH_X/LAUNCH_X-SEMANA_1/10%20-%20Manejo%20de%20Errores/Kata%20%26%20M%C3%B3dulo%2010/kata-modulo_10.ipynb#ch0000046?line=5'>6</a>\u001b[0m     \u001b[39mraise\u001b[39;00m \u001b[39mRuntimeError\u001b[39;00m(\u001b[39mf\u001b[39m\u001b[39m\"\u001b[39m\u001b[39mThere is not enough water for \u001b[39m\u001b[39m{\u001b[39;00mastronauts\u001b[39m}\u001b[39;00m\u001b[39m astronauts after \u001b[39m\u001b[39m{\u001b[39;00mdays_left\u001b[39m}\u001b[39;00m\u001b[39m days!\u001b[39m\u001b[39m\"\u001b[39m)\n\u001b[0;32m      <a href='vscode-notebook-cell:/d%3A/Users/EmmaD/Documents/10%20-%20PRACTICE/WEB%20DEV/3%20-%20COURSES/LAUNCH_X/LAUNCH_X-SEMANA_1/10%20-%20Manejo%20de%20Errores/Kata%20%26%20M%C3%B3dulo%2010/kata-modulo_10.ipynb#ch0000046?line=6'>7</a>\u001b[0m \u001b[39mreturn\u001b[39;00m \u001b[39mf\u001b[39m\u001b[39m\"\u001b[39m\u001b[39mTotal water left after \u001b[39m\u001b[39m{\u001b[39;00mdays_left\u001b[39m}\u001b[39;00m\u001b[39m days is: \u001b[39m\u001b[39m{\u001b[39;00mtotal_water_left\u001b[39m}\u001b[39;00m\u001b[39m liters\u001b[39m\u001b[39m\"\u001b[39m\n",
      "\u001b[1;31mRuntimeError\u001b[0m: There is not enough water for 5 astronauts after 2 days!"
     ]
    }
   ],
   "source": [
    "water_left(5, 100, 2)"
   ]
  },
  {
   "cell_type": "markdown",
   "metadata": {},
   "source": [
    "Esto no es muy útil, ya que una carencia en los litros sería un error. Después, el sistema de navegación podría alertar a los astronautas que no habrá suficiente agua para todos en dos días. Si eres un ingeniero(a) que programa el sistema de navegación, podrías generar una excepción en la función water_left() para alertar de la condición de error:"
   ]
  },
  {
   "cell_type": "code",
   "execution_count": 8,
   "metadata": {},
   "outputs": [],
   "source": [
    "def water_left(astronauts, water_left, days_left):\n",
    "    daily_usage = astronauts * 11\n",
    "    total_usage = daily_usage * days_left\n",
    "    total_water_left = water_left - total_usage\n",
    "    if total_water_left < 0:\n",
    "        raise RuntimeError(f\"There is not enough water for {astronauts} astronauts after {days_left} days!\")\n",
    "    return f\"Total water left after {days_left} days is: {total_water_left} liters\""
   ]
  },
  {
   "cell_type": "markdown",
   "metadata": {},
   "source": [
    "Ahora volvemos a ejecutarlo\n"
   ]
  },
  {
   "cell_type": "code",
   "execution_count": null,
   "metadata": {},
   "outputs": [],
   "source": [
    ">>> water_left(5, 100, 2)\n",
    "Traceback (most recent call last):\n",
    "  File \"<stdin>\", line 1, in <module>\n",
    "  File \"<stdin>\", line 6, in water_left\n",
    "RuntimeError: There is not enough water for 5 astronauts after 2 days!"
   ]
  },
  {
   "cell_type": "markdown",
   "metadata": {},
   "source": [
    "En el sistema de navegación, el código para señalar la alerta ahora puede usar RuntimeError para generar la alerta:\n",
    "\n"
   ]
  },
  {
   "cell_type": "code",
   "execution_count": null,
   "metadata": {},
   "outputs": [],
   "source": [
    "try:\n",
    "    water_left(5, 100, 2)\n",
    "except RuntimeError as err:\n",
    "    alert_navigation_system(err)"
   ]
  },
  {
   "cell_type": "markdown",
   "metadata": {},
   "source": [
    "La función water_left() también se puede actualizar para evitar el paso de tipos no admitidos. Intentenis pasar argumentos que no sean enteros para comprobar la salida de error:"
   ]
  },
  {
   "cell_type": "code",
   "execution_count": null,
   "metadata": {},
   "outputs": [],
   "source": [
    ">>> water_left(\"3\", \"200\", None)\n",
    "Traceback (most recent call last):\n",
    "  File \"<stdin>\", line 1, in <module>\n",
    "  File \"<stdin>\", line 3, in water_left\n",
    "TypeError: can't multiply sequence by non-int of type 'NoneType'"
   ]
  },
  {
   "cell_type": "markdown",
   "metadata": {},
   "source": [
    "El error de TypeError no es muy descriptivo en el contexto de lo que espera la función. Actualizaremos la función para que use TypeError, pero con un mensaje mejor:\n",
    "\n"
   ]
  },
  {
   "cell_type": "code",
   "execution_count": null,
   "metadata": {},
   "outputs": [],
   "source": [
    "def water_left(astronauts, water_left, days_left):\n",
    "    for argument in [astronauts, water_left, days_left]:\n",
    "        try:\n",
    "            # If argument is an int, the following operation will work\n",
    "            argument / 10\n",
    "        except TypeError:\n",
    "            # TypError will be raised only if it isn't the right type \n",
    "            # Raise the same exception but with a better error message\n",
    "            raise TypeError(f\"All arguments must be of type int, but received: '{argument}'\")\n",
    "    daily_usage = astronauts * 11\n",
    "    total_usage = daily_usage * days_left\n",
    "    total_water_left = water_left - total_usage\n",
    "    if total_water_left < 0:\n",
    "        raise RuntimeError(f\"There is not enough water for {astronauts} astronauts after {days_left} days!\")\n",
    "    return f\"Total water left after {days_left} days is: {total_water_left} liters\""
   ]
  },
  {
   "cell_type": "markdown",
   "metadata": {},
   "source": [
    "Ahora volvemos a intentarlo para obtener un error mejor:\n",
    "\n"
   ]
  },
  {
   "cell_type": "code",
   "execution_count": null,
   "metadata": {},
   "outputs": [],
   "source": [
    ">>> water_left(\"3\", \"200\", None)\n",
    "Traceback (most recent call last):\n",
    "  File \"<stdin>\", line 5, in water_left\n",
    "TypeError: unsupported operand type(s) for /: 'str' and 'int'\n",
    "\n",
    "During handling of the preceding exception, another exception occurred:\n",
    "\n",
    "Traceback (most recent call last):\n",
    "  File \"<stdin>\", line 1, in <module>\n",
    "  File \"<stdin>\", line 9, in water_left\n",
    "TypeError: All arguments must be of type int, but received: '3'"
   ]
  }
 ],
 "metadata": {
  "interpreter": {
   "hash": "085635c7bab703e7bb5a41fe64c7278518d529ae783e191374674f75ba478b45"
  },
  "kernelspec": {
   "display_name": "Python 3.10.2 64-bit",
   "language": "python",
   "name": "python3"
  },
  "language_info": {
   "codemirror_mode": {
    "name": "ipython",
    "version": 3
   },
   "file_extension": ".py",
   "mimetype": "text/x-python",
   "name": "python",
   "nbconvert_exporter": "python",
   "pygments_lexer": "ipython3",
   "version": "3.10.2"
  },
  "orig_nbformat": 4
 },
 "nbformat": 4,
 "nbformat_minor": 2
}
